<?xml version="1.0" encoding="utf-8"?>
<!-- =================================================================================== -->
<!-- |    This document was autogenerated by xacro from shivaa_manipulator.urdf.xacro  | -->
<!-- |    EDITING THIS FILE BY HAND IS NOT RECOMMENDED                                 | -->
<!-- =================================================================================== -->
<!-- This URDF was automatically created by SolidWorks to URDF Exporter! Originally created by Stephen Brawner (brawner@gmail.com) 
     Commit Version: 1.6.0-4-g7f85cfe  Build Version: 1.6.7995.38578
     For more information, please see http://wiki.ros.org/sw_urdf_exporter -->
<robot name="shivaa_arm">
  
  <link name="base_link_al">
    <inertial>
      <origin rpy="0 0 0" xyz="2.5849E-20 0 -1.3878E-17"/>
      <mass value="1.12E-06"/>
      <inertia ixx="1.8667E-13" ixy="6.2788E-30" ixz="5.8715E-30" iyy="1.8667E-13" iyz="-1.5387E-29" izz="1.8667E-13"/>
    </inertial>
    <visual>
      <origin rpy="0 0 0" xyz="0 0 0"/>
      <geometry>
        <mesh filename="/home/chris/robotic_research/publications/white_paper_kinematics/code/BeltManipulator/urdf/meshes/base_link_al.STL"/>
      </geometry>
      <material name="">
        <color rgba="0.394 0.008 0.293 1"/>
      </material>
    </visual>
    <collision>
      <origin rpy="0 0 0" xyz="0 0 0"/>
      <geometry>
        <mesh filename=".urdf/meshes/base_link_al.STL"/>
      </geometry>
    </collision>
  </link>
  
  <link name="link_prismatic">
    <inertial>
      <origin rpy="0 0 0" xyz="-0.023234 0.080829 2.4543E-05"/>
      <mass value="5.2318"/>
      <inertia ixx="0.019984" ixy="0.00074931" ixz="3.2214E-08" iyy="0.0096481" iyz="1.6688E-05" izz="0.016062"/>
    </inertial>
    <visual>
      <origin rpy="0 1.5708 0" xyz="0 0 0"/>
      <geometry>
        <mesh filename="/home/chris/robotic_research/publications/white_paper_kinematics/code/BeltManipulator/urdf/meshes/base_link_motor.STL"/>
      </geometry>
      <material name="">
        <color rgba="0.007 1 0.007 1"/>
      </material>
    </visual>
    <collision>
      <origin rpy="0 0 0" xyz="0 0 0"/>
      <geometry>
        <mesh filename=".urdf/meshes/base_link_motor.STL"/>
      </geometry>
    </collision>
  </link>
  <joint name="joint_arm_prismatic" type="fixed">
    <origin rpy="0 -1.5708 0" xyz="0 -0.5 -0.07"/>
    <parent link="base_link_al"/>
    <child link="link_prismatic"/>
    <axis xyz="0 0 1"/>
    <limit effort="0" lower="0" upper="0" velocity="0"/>
  </joint>
  <link name="link_1">
    <inertial>
      <origin rpy="0 0 0" xyz="0.15216 0.0046526 0.006534"/>
      <mass value="1.0992"/>
      <inertia ixx="0.00073454" ixy="4.0799E-05" ixz="-1.731E-07" iyy="0.013549" iyz="-2.1921E-07" izz="0.01393"/>
    </inertial>
    <visual>
      <origin rpy="0 0 0" xyz="0 0 0"/>
      <geometry>
        <mesh filename="/home/chris/robotic_research/publications/white_paper_kinematics/code/BeltManipulator/urdf/meshes/link_1.STL"/>
      </geometry>
      <material name="">
        <color rgba="0.12156862745098039 0.6235294117647059 0.47058823529411764 1"/>
      </material>
    </visual>
    <collision>
      <origin rpy="0 0 0" xyz="0 0 0"/>
      <geometry>
        <mesh filename=".urdf/meshes/link_1.STL"/>
      </geometry>
    </collision>
  </link>
  <joint name="joint_arm_1" type="revolute">
    <origin rpy="0 0 -3.1416" xyz="0 0 0"/>
    <parent link="link_prismatic"/>
    <child link="link_1"/>
    <axis xyz="0 0 -1"/>
    <limit effort="10" lower="3" upper="3" velocity="10"/>
  </joint>
  <link name="link_2">
    <inertial>
      <origin rpy="0 0 0" xyz="0.11197 -0.00074957 0.00096758"/>
      <mass value="0.75688"/>
      <inertia ixx="0.00050306" ixy="1.6316E-05" ixz="-7.3419E-09" iyy="0.0063415" iyz="-1.5272E-09" izz="0.0063518"/>
    </inertial>
    <visual>
      <origin rpy="0 0 0" xyz="0 0 0"/>
      <geometry>
        <mesh filename="/home/chris/robotic_research/publications/white_paper_kinematics/code/BeltManipulator/urdf/meshes/link_2.STL"/>
      </geometry>
      <material name="">
        <color rgba="0.8509803921568627 0.3803921568627451 0.023529411764705882 1"/>
      </material>
    </visual>
    <collision>
      <origin rpy="0 0 0" xyz="0 0 0"/>
      <geometry>
        <mesh filename=".urdf/meshes/link_2.STL"/>
      </geometry>
    </collision>
  </link>
  <joint name="joint_arm_2" type="revolute">
    <origin rpy="0 0 0" xyz="0.4 0 0"/>
    <parent link="link_1"/>
    <child link="link_2"/>
    <axis xyz="0 0 -1"/>
    <limit effort="6" lower="-3" upper="3" velocity="10"/>
  </joint>
  <link name="link_3">
    <inertial>
      <origin rpy="0 0 0" xyz="0.0063259 -4.1121E-06 5.5886E-08"/>
      <mass value="0.14631"/>
      <inertia ixx="3.8635E-05" ixy="5.7583E-11" ixz="1.1138E-09" iyy="2.9839E-05" iyz="1.4436E-11" izz="4.4725E-05"/>
    </inertial>
    <visual>
      <origin rpy="0 0 0" xyz="0 0 0"/>
      <geometry>
        <mesh filename="/home/chris/robotic_research/publications/white_paper_kinematics/code/BeltManipulator/urdf/meshes/link_3.STL"/>
      </geometry>
      <material name="">
        <color rgba="0.47058823529411764 0.45098039215686275 0.7058823529411765 1"/>
      </material>
    </visual>
    <collision>
      <origin rpy="0 0 0" xyz="0 0 0"/>
      <geometry>
        <mesh filename=".urdf/meshes/link_3.STL"/>
      </geometry>
    </collision>
  </link>
  <joint name="joint_arm_3" type="revolute">
    <origin rpy="0 0 0" xyz="0.398 0 0"/>
    <parent link="link_2"/>
    <child link="link_3"/>
    <axis xyz="0 0 -1"/>
    <limit effort="2" lower="-3" upper="3" velocity="5"/>
  </joint>
  <link name="link_4">
    <inertial>
      <origin rpy="0 0 0" xyz="-0.00075263 0.0025787 0.10253"/>
      <!-- <mass value="0.36192"/> -->
      <!-- Changing to payload capacity -->
      <mass value="1.0"/>
      <inertia ixx="0.00026029" ixy="1.4333E-06" ixz="3.2902E-07" iyy="0.00026203" iyz="-1.8815E-07" izz="3.3846E-04"/>
    </inertial>
    <visual>
      <origin rpy="0 0 0" xyz="0 0 0"/>
      <geometry>
        <mesh filename="/home/chris/robotic_research/publications/white_paper_kinematics/code/BeltManipulator/urdf/meshes/link_4.STL"/>
      </geometry>
      <material name="">
        <color rgba="0.9058823529411765 0.17647058823529413 0.5490196078431373 1"/>
      </material>
    </visual>
    <collision>
      <origin rpy="0 0 0" xyz="0 0 0"/>
      <geometry>
        <mesh filename=".urdf/meshes/link_4.STL"/>
      </geometry>
    </collision>
  </link>
  <joint name="joint_arm_4" type="revolute">
    <origin rpy="0 1.5708 0" xyz="0 0 0"/>
    <parent link="link_3"/>
    <child link="link_4"/>
    <axis xyz="0 0 1"/>
    <limit effort="2" lower="-3" upper="3" velocity="5"/>
  </joint>
</robot>
